#VRML_SIM R2025a utf8

PROTO robot_v1 [
  field SFVec3f    translation 0 0 0.1
  field SFRotation rotation    0 0 1 0
  field SFString   name        "Smart_Garbage_Collector"
  field SFString   controller  "keyboard_driver"
]
{
  Robot {
    translation IS translation
    rotation IS rotation
    name IS name
    controller IS controller
    
    children [
      # --- 1. 카메라 (ㅗ 상단) ---
      Transform {
        translation 0 -0.15 0.16
        rotation 0 0 1 3.14159
        children [
          Camera { name "camera" fieldOfView 1.0 width 640 height 480 }
          Shape { appearance PBRAppearance { baseColor 0.2 0.2 0.8 } geometry Box { size 0.03 0.03 0.03 } }
        ]
      }
      
      # --- 2. 로봇 몸체 ('ㅗ' 모양) ---
      Group {
        children [
          Transform { translation 0 -0.15 -0.02 children [ Shape { appearance PBRAppearance { baseColor 0.1 0.1 0.1 } geometry Box { size 0.36 0.06 0.06 } } ] }
          Transform { translation 0 -0.15 0.08 children [ Shape { appearance PBRAppearance { baseColor 0.1 0.1 0.1 } geometry Box { size 0.12 0.06 0.14 } } ] }
          Transform { translation -0.15 0 -0.02 children [ Shape { appearance PBRAppearance { baseColor 0.1 0.1 0.1 } geometry Box { size 0.06 0.24 0.06 } } ] }
          Transform { translation 0.15 0 -0.02 children [ Shape { appearance PBRAppearance { baseColor 0.1 0.1 0.1 } geometry Box { size 0.06 0.24 0.06 } } ] }
        ]
      }
      
      # --- 3. 앞바퀴 (조향: steer_left, steer_right) ---
      Hinge2Joint {
        jointParameters HingeJointParameters { anchor -0.2 0.08 -0.05 axis 0 0 1 }
        jointParameters2 JointParameters { axis 1 0 0 friction 0.01 }
        device [ RotationalMotor { name "steer_left" minPosition -0.5 maxPosition 0.5 } ]
        endPoint Solid {
          translation -0.2 0.08 -0.05 rotation 0 1 0 1.5708
          children [ Shape { appearance PBRAppearance { baseColor 0.8 0.2 0.2 } geometry Cylinder { height 0.04 radius 0.05 } } ]
          name "wheel1"
          contactMaterial "wheel_mat"
          boundingObject Cylinder { height 0.04 radius 0.05 }
          physics Physics { density -1 mass 1.0 }
        }
      }
      Hinge2Joint {
        jointParameters HingeJointParameters { anchor 0.2 0.08 -0.05 axis 0 0 1 }
        jointParameters2 JointParameters { axis 1 0 0 friction 0.01 }
        device [ RotationalMotor { name "steer_right" minPosition -0.5 maxPosition 0.5 } ]
        endPoint Solid {
          translation 0.2 0.08 -0.05 rotation 0 1 0 1.5708
          children [ Shape { appearance PBRAppearance { baseColor 0.8 0.2 0.2 } geometry Cylinder { height 0.04 radius 0.05 } } ]
          name "wheel2"
          contactMaterial "wheel_mat"
          boundingObject Cylinder { height 0.04 radius 0.05 }
          physics Physics { density -1 mass 1.0 }
        }
      }
      
      # --- 4. 뒷바퀴 (구동: drive_left, drive_right) ---
      HingeJoint {
        jointParameters HingeJointParameters { anchor -0.2 -0.15 -0.05 axis 1 0 0 }
        device [ RotationalMotor { name "drive_left" acceleration 5 availableTorque 30 } ]
        endPoint Solid {
          translation -0.2 -0.15 -0.05 rotation 0 1 0 1.5708
          children [ Shape { appearance PBRAppearance { baseColor 0.8 0.2 0.2 } geometry Cylinder { height 0.04 radius 0.05 } } ]
          name "wheel3"
          contactMaterial "wheel_mat"
          boundingObject Cylinder { height 0.04 radius 0.05 }
          physics Physics { density -1 mass 1.0 }
        }
      }
      HingeJoint {
        jointParameters HingeJointParameters { anchor 0.2 -0.15 -0.05 axis 1 0 0 }
        device [ RotationalMotor { name "drive_right" acceleration 5 availableTorque 30 } ]
        endPoint Solid {
          translation 0.2 -0.15 -0.05 rotation 0 1 0 1.5708
          children [ Shape { appearance PBRAppearance { baseColor 0.8 0.2 0.2 } geometry Cylinder { height 0.04 radius 0.05 } } ]
          name "wheel4"
          contactMaterial "wheel_mat"
          boundingObject Cylinder { height 0.04 radius 0.05 }
          physics Physics { density -1 mass 1.0 }
        }
      }
    ]

    # --- 충돌 범위 설정 ---
    boundingObject Group {
      children [
        Transform { translation 0 -0.15 -0.02 children [ Box { size 0.36 0.06 0.06 } ] }
        Transform { translation 0 -0.15 0.08 children [ Box { size 0.12 0.06 0.14 } ] }
        Transform { translation -0.15 0 -0.02 children [ Box { size 0.06 0.24 0.06 } ] }
        Transform { translation 0.15 0 -0.02 children [ Box { size 0.06 0.24 0.06 } ] }
      ]
    }
    
    # --- 전체 물리 법칙 ---
    physics Physics {
      density -1
      mass 18
      centerOfMass [ 0 0 0 ]
      damping Damping { linear 0.2 angular 0.5 }
    }
  }
}