#VRML_SIM R2025a utf8

PROTO SmartGarbageCollector [
<<<<<<< HEAD
  field SFVec3f    translation  0 0 0
  field SFRotation rotation     0 0 1 0
  field SFString   controller   "Robot_controller"
=======
  field SFVec3f    translation 0 0 0.05
  field SFRotation rotation    0 0 1 0
  field SFString   name        "Smart_Garbage_Collector"
  field SFString   controller  "Robot_controller"
  field SFColor    bodyColor   0.2 0.2 0.2
>>>>>>> 1dfb623ff3077b35e12f64da68958d562afaf695
]
{
  Robot {
  translation IS translation
  rotation IS rotation
  children [
    HingeJoint {
      jointParameters HingeJointParameters {
        position 1.1718944681279232e-07
        axis 0 1 0
        anchor 0.11 0.1485 0
      }
      device [
        RotationalMotor {
          name "front_left_motor"
          maxVelocity 20
          maxTorque 50
        }
      ]
      endPoint Solid {
        translation 0.11 0.1485 0
        rotation 0 1 0 1.1542389828584842e-07
        children [
<<<<<<< HEAD
          Transform {
            rotation 0 0 1 -1.5708
            scale 0.001 0.001 0.001
            children [
              Shape {
                appearance PBRAppearance {
                  baseColorMap ImageTexture {
                    url [
                      "https://raw.githubusercontent.com/cyberbotics/webots/R2025a/projects/vehicles/protos/abstract/GenericTireAppearance/textures/tire_texture_base_color.jpg"
                    ]
                  }
                  roughness 0.8
                  roughnessMap ImageTexture {
                    url [
                      "https://raw.githubusercontent.com/cyberbotics/webots/R2025a/projects/vehicles/protos/abstract/GenericTireAppearance/textures/tire_texture_roughness.jpg"
                    ]
                  }
                  normalMap ImageTexture {
                    url [
                      "https://raw.githubusercontent.com/cyberbotics/webots/R2025a/projects/vehicles/protos/abstract/GenericTireAppearance/textures/tire_texture_normal.jpg"
                    ]
                  }
                  occlusionMap ImageTexture {
                    url [
                      "https://raw.githubusercontent.com/cyberbotics/webots/R2025a/projects/vehicles/protos/abstract/GenericTireAppearance/textures/tire_texture_occlusion.jpg"
                    ]
                  }
                }
                geometry Mesh {
                  url [
                    "/Users/lsy/Documents/Capstone/protos/Meshes/모듈 - 휠 2.stl"
                  ]
                }
              }
            ]
=======
          Shape {
            appearance PBRAppearance { baseColor IS bodyColor metalness 0 }
            geometry Mesh { url [ "Meshes/모듈 - 바디.stl" ] }
>>>>>>> 1dfb623ff3077b35e12f64da68958d562afaf695
          }
        ]
        name "wheel_fl"
        contactMaterial "rubber"
        boundingObject Pose {
          rotation 1 0 0 1.5708
          children [
            Cylinder {
              height 0.03
              radius 0.04
            }
          ]
        }
        physics Physics {
        }
      }
<<<<<<< HEAD
    }
    HingeJoint {
      jointParameters HingeJointParameters {
        position -8.705412568588144e-08
        axis 0 1 0
        anchor 0.11 -0.1485 0
      }
      device [
        RotationalMotor {
          name "front_right_motor"
          maxVelocity 20
          maxTorque 50
        }
      ]
      endPoint Solid {
        translation 0.11 -0.1485 0
        rotation 0 -1 0 8.940696716308595e-08
        children [
          Transform {
            rotation 0 0 1 -1.5708
            scale 0.001 0.001 0.001
            children [
              Shape {
                appearance PBRAppearance {
                  baseColorMap ImageTexture {
                    url [
                      "https://raw.githubusercontent.com/cyberbotics/webots/R2025a/projects/vehicles/protos/abstract/GenericTireAppearance/textures/tire_texture_base_color.jpg"
                    ]
                  }
                  roughness 0.8
                  roughnessMap ImageTexture {
                    url [
                      "https://raw.githubusercontent.com/cyberbotics/webots/R2025a/projects/vehicles/protos/abstract/GenericTireAppearance/textures/tire_texture_roughness.jpg"
                    ]
                  }
                  normalMap ImageTexture {
                    url [
                      "https://raw.githubusercontent.com/cyberbotics/webots/R2025a/projects/vehicles/protos/abstract/GenericTireAppearance/textures/tire_texture_normal.jpg"
                    ]
                  }
                  occlusionMap ImageTexture {
                    url [
                      "https://raw.githubusercontent.com/cyberbotics/webots/R2025a/projects/vehicles/protos/abstract/GenericTireAppearance/textures/tire_texture_occlusion.jpg"
                    ]
                  }
                }
                geometry Mesh {
                  url [
                    "/Users/lsy/Documents/Capstone/protos/Meshes/모듈 - 휠 2.stl"
                  ]
                }
              }
            ]
          }
        ]
        name "wheel_fr"
        contactMaterial "rubber"
        boundingObject Pose {
          rotation 1 0 0 1.5708
          children [
            Cylinder {
              height 0.03
              radius 0.04
            }
          ]
        }
        physics Physics {
        }
      }
    }
    Hinge2Joint {
      jointParameters HingeJointParameters {
        position 3.087085700662211e-11
        axis 0 0 1
        anchor -0.11 0.1485 0
      }
      jointParameters2 JointParameters {
        position 0.04742100244544065
        axis 0 1 0
      }
      device [
        RotationalMotor {
          name "steer_bl"
        }
      ]
      endPoint Solid {
        translation -0.11 0.1485 0
        rotation -1.5435428503311053e-11 1 6.508734553120878e-10 0.04742100244544071
        children [
          Transform {
            rotation 0 0 1 -1.5708
            scale 0.001 0.001 0.001
            children [
              Shape {
                appearance PBRAppearance {
                  baseColorMap ImageTexture {
                    url [
                      "https://raw.githubusercontent.com/cyberbotics/webots/R2025a/projects/vehicles/protos/abstract/GenericTireAppearance/textures/tire_texture_base_color.jpg"
                    ]
                  }
                  roughness 0.8
                  roughnessMap ImageTexture {
                    url [
                      "https://raw.githubusercontent.com/cyberbotics/webots/R2025a/projects/vehicles/protos/abstract/GenericTireAppearance/textures/tire_texture_roughness.jpg"
                    ]
                  }
                  normalMap ImageTexture {
                    url [
                      "https://raw.githubusercontent.com/cyberbotics/webots/R2025a/projects/vehicles/protos/abstract/GenericTireAppearance/textures/tire_texture_normal.jpg"
                    ]
                  }
                  occlusionMap ImageTexture {
                    url [
                      "https://raw.githubusercontent.com/cyberbotics/webots/R2025a/projects/vehicles/protos/abstract/GenericTireAppearance/textures/tire_texture_occlusion.jpg"
                    ]
                  }
                }
                geometry Mesh {
                  url [
                    "/Users/lsy/Documents/Capstone/protos/Meshes/모듈 - 휠 2.stl"
                  ]
                }
              }
            ]
          }
        ]
        name "wheel_bl"
        contactMaterial "rubber"
        boundingObject Pose {
          rotation 1 0 0 1.5708
          children [
            Cylinder {
              height 0.03
              radius 0.04
            }
          ]
        }
        physics Physics {
        }
      }
    }
    Hinge2Joint {
      jointParameters HingeJointParameters {
        position 6.960602097761846e-12
        axis 0 0 1
        anchor -0.11 -0.1485 0
      }
      jointParameters2 JointParameters {
        position 0.013193612389565804
        axis 0 1 0
      }
      device [
        RotationalMotor {
          name "steer_br"
        }
      ]
      endPoint Solid {
        translation -0.11 -0.1485 0
        rotation -3.4803010488809226e-12 1 5.275659858571458e-10 0.013193612389579674
        children [
          Transform {
            rotation 0 0 1 -1.5708
            scale 0.001 0.001 0.001
            children [
              Shape {
                appearance PBRAppearance {
                  baseColorMap ImageTexture {
                    url [
                      "https://raw.githubusercontent.com/cyberbotics/webots/R2025a/projects/vehicles/protos/abstract/GenericTireAppearance/textures/tire_texture_base_color.jpg"
                    ]
                  }
                  roughness 0.8
                  roughnessMap ImageTexture {
                    url [
                      "https://raw.githubusercontent.com/cyberbotics/webots/R2025a/projects/vehicles/protos/abstract/GenericTireAppearance/textures/tire_texture_roughness.jpg"
                    ]
                  }
                  normalMap ImageTexture {
                    url [
                      "https://raw.githubusercontent.com/cyberbotics/webots/R2025a/projects/vehicles/protos/abstract/GenericTireAppearance/textures/tire_texture_normal.jpg"
                    ]
                  }
                  occlusionMap ImageTexture {
                    url [
                      "https://raw.githubusercontent.com/cyberbotics/webots/R2025a/projects/vehicles/protos/abstract/GenericTireAppearance/textures/tire_texture_occlusion.jpg"
                    ]
                  }
                }
                geometry Mesh {
                  url [
                    "/Users/lsy/Documents/Capstone/protos/Meshes/모듈 - 휠 2.stl"
                  ]
                }
              }
            ]
          }
        ]
        name "wheel_br"
        contactMaterial "rubber"
        boundingObject Pose {
          rotation 1 0 0 1.5708
          children [
            Cylinder {
              height 0.03
              radius 0.04
            }
          ]
        }
        physics Physics {
        }
      }
    }
    DEF BODY_VISUAL Transform {
      scale 0.001 0.001 0.001
      children [
        Shape {
          appearance PBRAppearance {
            baseColor 0.2 0.2 0.2
            metalness 0
          }
          geometry Mesh {
            url [
              "/Users/lsy/Documents/Capstone/protos/Meshes/모듈 - 바디.stl"
            ]
          }
        }
      ]
    }
=======

      # --- [식별 마커: 로봇 위 컬러 구체] ---
      Transform {
        translation 0 0 0.28
        children [
          Shape {
            appearance PBRAppearance { baseColor IS bodyColor metalness 0.2 }
            geometry Sphere { radius 0.03 }
          }
        ]
      }

      # --- [센서부] 하드웨어 설계 명세서 3.3절 기준 ---

    # 📷 카메라 B: Intel RealSense D435 (후면 외측 - 주행/SLAM용)
    # 후방 시야를 담당하므로 180도 회전(3.14159)하여 배치합니다.
>>>>>>> 1dfb623ff3077b35e12f64da68958d562afaf695
    Pose {
      translation -0.125 0 0.25
      rotation 0 0 1 3.14159
      children [
        Camera {
          name "realsense_color"
          fieldOfView 1.204
          width 1280
          height 720
        }
        RangeFinder {
          name "realsense_depth"
          fieldOfView 1.204
          width 1280
          height 720
          minRange 0.1
          maxRange 10
        }
      ]
    }
    Camera {
      translation -0.115 0 0.25
      name "webcam_color"
      fieldOfView 1.396
      width 1920
      height 1080
    }
    DistanceSensor {
      translation -0.05 0.11 0.25
      name "us_front_left"
      lookupTable [
        0.002 0.002 0
        4 4 0.01
      ]
      type "sonar"
      numberOfRays 10
      aperture 0.26
      resolution 0.003
    }
<<<<<<< HEAD
    DistanceSensor {
      translation -0.05 -0.11 0.25
      name "us_front_right"
      lookupTable [
        0.002 0.002 0
        4 4 0.01
      ]
      type "sonar"
      numberOfRays 10
      aperture 0.26
      resolution 0.003
=======
    physics Physics {
      density -1
      mass 1.0
      centerOfMass [ 0.05 0 0.101 ] # 앞바퀴 접지력을 위해 약간 전진 배치
>>>>>>> 1dfb623ff3077b35e12f64da68958d562afaf695
    }
    DistanceSensor {
      translation -0.0875 0.125 0.2
      rotation 0 0 1 1.5708
      name "us_side_left"
      lookupTable [
        0.002 0.002 0
        4 4 0.01
      ]
      type "sonar"
      numberOfRays 10
      aperture 0.26
      resolution 0.003
    }
    DistanceSensor {
      translation -0.0875 -0.125 0.2
      rotation 0 0 1 -1.5708
      name "us_side_right"
      lookupTable [
        0.002 0.002 0
        4 4 0.01
      ]
      type "sonar"
      numberOfRays 10
      aperture 0.26
      resolution 0.003
    }
    DistanceSensor {
      translation -0.125 0 0.2
      rotation 0 0 1 3.14159
      name "us_rear"
      lookupTable [
        0.002 0.002 0
        4 4 0.01
      ]
      type "sonar"
      numberOfRays 10
      aperture 0.26
      resolution 0.003
    }
    InertialUnit {
      name "imu"
    }
    Gyro {
    }
    Accelerometer {
    }
  ]
  name "Smart_Garbage_Collector"
  boundingObject Group {
    children [
      Pose {
        translation 0.0375 -0.11 0.015
        children [
          Box {
            size 0.175 0.03 0.03
          }
        ]
      }
      Pose {
        translation 0.0375 0.11 0.015
        children [
          Box {
            size 0.175 0.03 0.03
          }
        ]
      }
      Pose {
        translation -0.0875 0 0.13
        children [
          Box {
            size 0.075 0.25 0.26
          }
        ]
      }
    ]
  }
  physics Physics {
    density -1
    mass 1
    centerOfMass [
      0.05 0 0.101
    ]
  }
  controller IS controller
}

}