#VRML_SIM R2025a utf8

EXTERNPROTO "https://raw.githubusercontent.com/cyberbotics/webots/R2025a/projects/objects/backgrounds/protos/TexturedBackground.proto"
EXTERNPROTO "https://raw.githubusercontent.com/cyberbotics/webots/R2025a/projects/objects/backgrounds/protos/TexturedBackgroundLight.proto"
EXTERNPROTO "https://raw.githubusercontent.com/cyberbotics/webots/R2025a/projects/vehicles/protos/abstract/GenericTireAppearance.proto"
EXTERNPROTO "https://raw.githubusercontent.com/cyberbotics/webots/R2025a/projects/objects/floors/protos/RectangleArena.proto"

WorldInfo {
}
Viewpoint {
  orientation -0.14693806992691066 0.07564164657931662 0.9862492306252635 2.2020232172186582
  position 0.7162568392683049 -0.8239958020566289 0.5334432112582908
}
TexturedBackground {
}
TexturedBackgroundLight {
}
RectangleArena {
  floorSize 20 20
}
Robot {
  translation 0 0 0.05
  children [
    Hinge2Joint {
      jointParameters HingeJointParameters {
        axis 0 0 1
        anchor 0.11 0.1485 0
      }
      jointParameters2 JointParameters {
        axis 0 1 0
      }
      device [
        RotationalMotor {
          name "steer_fl"
        }
      ]
      endPoint Solid {
        translation 0.11 0.1485 0
        children [
          Transform {
            rotation 0 0 1 -1.5707996938995747
            scale 0.001 0.001 0.001
            children [
              Shape {
                appearance GenericTireAppearance {
                }
                geometry Mesh {
                  url [
                    "../protos/Meshes/모듈 - 휠 2.stl"
                  ]
                }
              }
            ]
          }
        ]
        name "wheel_fl"
        boundingObject Pose {
          rotation 1 0 0 1.5708
          children [
            Cylinder {
              height 0.03
              radius 0.04
            }
          ]
        }
        physics Physics {
        }
      }
    }
    Hinge2Joint {
      jointParameters HingeJointParameters {
        axis 0 0 1
        anchor 0.11 -0.1485 0
      }
      jointParameters2 JointParameters {
        axis 0 1 0
      }
      device [
        RotationalMotor {
          name "steer_fr"
        }
      ]
      endPoint Solid {
        translation 0.11 -0.1485 0
        children [
          Transform {
            rotation 0 0 1 -1.5707996938995747
            scale 0.001 0.001 0.001
            children [
              Shape {
                appearance GenericTireAppearance {
                }
                geometry Mesh {
                  url [
                    "../protos/Meshes/모듈 - 휠 2.stl"
                  ]
                }
              }
            ]
          }
        ]
        name "wheel_fr"
        boundingObject Pose {
          rotation 1 0 0 1.5708
          children [
            Cylinder {
              height 0.03
              radius 0.04
            }
          ]
        }
        physics Physics {
        }
      }
    }
    HingeJoint {
      jointParameters HingeJointParameters {
        axis 0 1 0
        anchor -0.11 0.1485 0
      }
      device [
        RotationalMotor {
          name "drive_bl"
        }
      ]
      endPoint Solid {
        translation -0.11 0.1485 0
        children [
          Transform {
            rotation 0 0 1 -1.5707996938995747
            scale 0.001 0.001 0.001
            children [
              Shape {
                appearance GenericTireAppearance {
                }
                geometry Mesh {
                  url [
                    "../protos/Meshes/모듈 - 휠 2.stl"
                  ]
                }
              }
            ]
          }
        ]
        name "wheel_bl"
        boundingObject Pose {
          rotation 1 0 0 1.5708
          children [
            Cylinder {
              height 0.03
              radius 0.04
            }
          ]
        }
        physics Physics {
        }
      }
    }
    HingeJoint {
      jointParameters HingeJointParameters {
        axis 0 1 0
        anchor -0.11 -0.1485 0
      }
      device [
        RotationalMotor {
          name "drive_br"
        }
      ]
      endPoint Solid {
        translation -0.11 -0.1485 0
        children [
          Transform {
            rotation 0 0 1 -1.5707996938995747
            scale 0.001 0.001 0.001
            children [
              Shape {
                appearance GenericTireAppearance {
                }
                geometry Mesh {
                  url [
                    "../protos/Meshes/모듈 - 휠 2.stl"
                  ]
                }
              }
            ]
          }
        ]
        name "wheel_br"
        boundingObject Pose {
          rotation 1 0 0 1.5708
          children [
            Cylinder {
              height 0.03
              radius 0.04
            }
          ]
        }
        physics Physics {
        }
      }
    }
    DEF BODY_VISUAL Transform {
      scale 0.001 0.001 0.001
      children [
        Shape {
          appearance PBRAppearance {
            baseColor 0.2 0.2 0.2
            metalness 0
          }
          geometry Mesh {
            url [
              "../protos/Meshes/모듈 - 바디.stl"
            ]
          }
        }
      ]
    }
  ]
  name "Robot"
  boundingObject Group {
    children [
      Pose {
        translation 0.0375 -0.11 0.015
        children [
          Box {
            size 0.175 0.03 0.03
          }
        ]
      }
      Pose {
        translation 0.0375 0.11 0.015
        children [
          Box {
            size 0.175 0.03 0.03
          }
        ]
      }
      Pose {
        translation -0.0875 0 0.13
        children [
          Box {
            size 0.075 0.25 0.26
          }
        ]
      }
    ]
  }
  physics Physics {
    density -1
    mass 1
    centerOfMass [
      -0.07 0 0.101
    ]
  }
  controller "Robot_controller"
}
